<?xml version="1.0" encoding="utf-8"?>

<robot xmlns:xacro="http://www.ros.org/wiki/xacro"
  name="Autonomous lawn mower">
  <xacro:include filename="$(find robot_description)/urdf/plugins.xacro" />

  <link name="robot_footprint" />

  <joint name="robot_footprint_joint" type="fixed">
    <origin rpy="0 0 0" xyz="0 0 0.36" />
    <parent link="robot_footprint" />
    <child link="base_link" />
  </joint>

  <link
    name="base_link">
    <inertial>
      <origin
        xyz="0.094793288501067 -6.66133814775094E-16 -0.167839900892151"
        rpy="0 0 0" />
      <mass
        value="4.48064143405994" />
      <inertia
        ixx="0.0491390017279083"
        ixy="-6.26091486837186E-17"
        ixz="-1.33937628526678E-07"
        iyy="0.170856978277775"
        iyz="-2.72940768243986E-07"
        izz="0.213792245249315" />
    </inertial>
    <visual>
      <origin
        xyz="0 0 0"
        rpy="0 0 0" />
      <geometry>
        <mesh
          filename="package://robot_description/meshes/base_link.STL" />
      </geometry>
      <material
        name="">
        <color
          rgba="0.792156862745098 0.819607843137255 0.933333333333333 1" />
      </material>
    </visual>
    <collision>
      <origin
        xyz="0 0 0"
        rpy="0 0 0" />
      <geometry>
        <mesh
          filename="package://robot_description/meshes/base_link.STL" />
      </geometry>
    </collision>
  </link>


  <link
    name="Link_FL">
    <inertial>
      <origin
        xyz="-2.7756E-17 -0.022487 1.1102E-16"
        rpy="0 0 0" />
      <mass
        value="0.96666" />
      <inertia
        ixx="0.0018187"
        ixy="-3.477E-19"
        ixz="2.9143E-33"
        iyy="0.0033144"
        iyz="-1.1068E-17"
        izz="0.0018187" />
    </inertial>
    <visual>
      <origin
        xyz="0 0 0"
        rpy="0 0 0" />
      <geometry>
        <mesh
          filename="package://robot_description/meshes/Link_FL.STL" />
      </geometry>
      <material
        name="">
        <color
          rgba="0.79216 0.81961 0.93333 1" />
      </material>
    </visual>
    <collision>
      <origin
        xyz="0 0 0"
        rpy="0 0 0" />
      <geometry>
        <mesh
          filename="package://robot_description/meshes/Link_FL.STL" />
      </geometry>
    </collision>
  </link>

  <!-- Now attach the wheel to the steering link with a fixed joint -->
  <joint name="wheel_fl_drive" type="continuous">
    <origin xyz="0.35347 0.3075 -0.287" rpy="0 0 0" />
    <parent link="base_link" />
    <child link="Link_FL" />
    <axis xyz="0 1 0" />
    <limit effort="10" velocity="10" />
    <dynamics damping="1.0" friction="1.0"/>
  </joint>


  <link
    name="Link_BL">
    <inertial>
      <origin
        xyz="0 -0.022487 -2.2204E-16"
        rpy="0 0 0" />
      <mass
        value="0.96666" />
      <inertia
        ixx="0.0018187"
        ixy="-1.3118E-21"
        ixz="2.6437E-19"
        iyy="0.0033144"
        iyz="9.6413E-19"
        izz="0.0018187" />
    </inertial>
    <visual>
      <origin
        xyz="0 0 0"
        rpy="0 0 0" />
      <geometry>
        <mesh
          filename="package://robot_description/meshes/Link_BL.STL" />
      </geometry>
      <material
        name="">
        <color
          rgba="0.79216 0.81961 0.93333 1" />
      </material>
    </visual>
    <collision>
      <origin
        xyz="0 0 0"
        rpy="0 0 0" />
      <geometry>
        <mesh
          filename="package://robot_description/meshes/Link_BL.STL" />
      </geometry>
    </collision>
  </link>

  <joint name="wheel_BL_joint" type="continuous">
    <origin xyz="-0.41347 0.3075 -0.287" rpy="0 0 0" />
    <parent link="base_link" />
    <child link="Link_BL" />
    <axis xyz="0 1 0" />
    <limit effort="10" velocity="10" />
    <dynamics damping="1.0" friction="1.0"/>
  </joint>

  <link
    name="Link_BR">
    <inertial>
      <origin
        xyz="-8.8818E-16 0.022487 -3.3307E-16"
        rpy="0 0 0" />
      <mass
        value="0.96666" />
      <inertia
        ixx="0.0018187"
        ixy="-5.2186E-17"
        ixz="2.6431E-21"
        iyy="0.0033144"
        iyz="-1.0664E-17"
        izz="0.0018187" />
    </inertial>
    <visual>
      <origin
        xyz="0 0 0"
        rpy="0 0 0" />
      <geometry>
        <mesh
          filename="package://robot_description/meshes/Link_BR.STL" />
      </geometry>
      <material
        name="">
        <color
          rgba="0.79216 0.81961 0.93333 1" />
      </material>
    </visual>
    <collision>
      <origin
        xyz="0 0 0"
        rpy="0 0 0" />
      <geometry>
        <mesh
          filename="package://robot_description/meshes/Link_BR.STL" />
      </geometry>
    </collision>
  </link>

  <joint name="wheel_BR_joint" type="continuous">
    <origin xyz="-0.41347 -0.3075 -0.287" rpy="0 0 0" />
    <parent link="base_link" />
    <child link="Link_BR" />
    <axis xyz="0 1 0" />
    <limit effort="10" velocity="10" />
    <dynamics damping="1.0" friction="1.0"/>
  </joint>

  <link
    name="Link_FR">
    <inertial>
      <origin
        xyz="-8.0491E-16 0.022487 -2.2204E-16"
        rpy="0 0 0" />
      <mass
        value="0.96666" />
      <inertia
        ixx="0.0018187"
        ixy="-5.2657E-17"
        ixz="-5.6271E-21"
        iyy="0.0033144"
        iyz="5.8746E-19"
        izz="0.0018187" />
    </inertial>
    <visual>
      <origin
        xyz="0 0 0"
        rpy="0 0 0" />
      <geometry>
        <mesh
          filename="package://robot_description/meshes/Link_FR.STL" />
      </geometry>
      <material
        name="">
        <color
          rgba="0.79216 0.81961 0.93333 1" />
      </material>
    </visual>
    <collision>
      <origin
        xyz="0 0 0"
        rpy="0 0 0" />
      <geometry>
        <mesh
          filename="package://robot_description/meshes/Link_FR.STL" />
      </geometry>
    </collision>
  </link>

  <!-- Now attach the wheel to the steering link with a fixed joint -->
  <joint name="wheel_fr_drive" type="continuous">
    <origin xyz="0.35347 -0.3075 -0.287" rpy="0 0 0" />
    <parent link="base_link" />
    <child link="Link_FR" />
    <axis xyz="0 1 0" />
    <limit effort="10" velocity="10" />
    <dynamics damping="1.0" friction="1.0"/>
  </joint>

  <!-- RPLIDAR Link with proper geometry -->
  <link name="rplidar_link">
    <inertial>
      <origin xyz="0 0 0" rpy="0 0 0" />
      <mass value="0.2" />
      <inertia ixx="0.001" ixy="0.0" ixz="0.0" iyy="0.001" iyz="0.0" izz="0.001" />
    </inertial>
    <visual>
      <origin xyz="0 0 0" rpy="0 0 0" />
      <geometry>
        <cylinder radius="0.035" length="0.04" />
      </geometry>
      <material name="lidar_material">
        <color rgba="1.0 0.3 0.5 1.0" />  <!-- Bright red for visibility -->
      </material>
    </visual>
    <collision>
      <origin xyz="0 0 0" rpy="0 0 0" />
      <geometry>
        <cylinder radius="0.035" length="0.04" />
      </geometry>
    </collision>
  </link>

  <!-- RPLIDAR Joint - positioned higher for better scanning -->
  <joint name="rplidar_joint" type="fixed">
    <origin xyz="0.15 0 0.025" rpy="0 0 0" />  <!-- Raised from 0.025 to 0.1 -->
    <parent link="base_link" />
    <child link="rplidar_link" />
  </joint>
</robot>